<?xml version="1.0" ?>
<robot name="robot_dog">
  <link name="base_link">
    <inertial>
      <origin xyz="0 0 0" rpy="0 0 0"/>
      <mass value="0.5"/>
      <inertia ixx="0.0007499999999999999" ixy="0" ixz="0" iyy="0.0039000000000000003" iyz="0" izz="0.00435"/>
    </inertial>
    <visual>
      <origin xyz="0 0 0" rpy="0 0 0"/>
      <geometry>
        <box size="0.3 0.12 0.06"/>
      </geometry>
      <material name="blue">
        <color rgba="0.2 0.4 0.8 1"/>
      </material>
    </visual>
    <collision>
      <origin xyz="0 0 0" rpy="0 0 0"/>
      <geometry>
        <box size="0.3 0.12 0.06"/>
      </geometry>
    </collision>
  </link>
  <link name="FL_hip_link">
    <inertial>
      <origin xyz="0 0.025 0" rpy="0 0 0"/>
      <mass value="0.03"/>
      <inertia ixx="8.68e-06" ixy="0" ixz="0" iyy="4.859999999999998e-06" iyz="0" izz="8.68e-06"/>
    </inertial>
    <visual>
      <origin xyz="0 0.025 0" rpy="1.5708 0 0"/>
      <geometry>
        <cylinder radius="0.018" length="0.05"/>
      </geometry>
      <material name="grey">
        <color rgba="0.4 0.4 0.45 1"/>
      </material>
    </visual>
    <collision>
      <origin xyz="0 0.025 0" rpy="1.5708 0 0"/>
      <geometry>
        <cylinder radius="0.018" length="0.05"/>
      </geometry>
    </collision>
  </link>
  <joint name="FL_abd" type="revolute">
    <parent link="base_link"/>
    <child link="FL_hip_link"/>
    <origin xyz="0.12 0.06 0" rpy="0 0 0"/>
    <axis xyz="1.0 0 0"/>
    <limit lower="-1.0" upper="1.0" effort="0.2" velocity="6.0"/>
  </joint>
  <link name="FL_shank">
    <inertial>
      <origin xyz="0 0 -0.065" rpy="0 0 0"/>
      <mass value="0.015"/>
      <inertia ixx="2.1758750000000002e-05" ixy="0" ixz="0" iyy="2.1758750000000002e-05" iyz="0" izz="1.2675e-06"/>
    </inertial>
    <visual>
      <origin xyz="0 0 -0.065" rpy="0 0 0"/>
      <geometry>
        <cylinder radius="0.013" length="0.13"/>
      </geometry>
      <material name="green">
        <color rgba="0.2 0.7 0.3 1"/>
      </material>
    </visual>
    <collision>
      <origin xyz="0 0 -0.065" rpy="0 0 0"/>
      <geometry>
        <cylinder radius="0.013" length="0.13"/>
      </geometry>
    </collision>
  </link>
  <joint name="FL_knee" type="revolute">
    <parent link="FL_hip_link"/>
    <child link="FL_shank"/>
    <origin xyz="0 0.05 0" rpy="0 0 0"/>
    <axis xyz="0 1 0"/>
    <limit lower="-1.5" upper="1.5" effort="0.2" velocity="6.0"/>
  </joint>
  <link name="FL_foot">
    <inertial>
      <origin xyz="0 0 0" rpy="0 0 0"/>
      <mass value="0.02"/>
      <inertia ixx="2.048e-06" ixy="0" ixz="0" iyy="2.048e-06" iyz="0" izz="2.048e-06"/>
    </inertial>
    <visual>
      <origin xyz="0 0 0" rpy="0 0 0"/>
      <geometry>
        <sphere radius="0.016"/>
      </geometry>
      <material name="grey">
        <color rgba="0.4 0.4 0.45 1"/>
      </material>
    </visual>
    <collision>
      <origin xyz="0 0 0" rpy="0 0 0"/>
      <geometry>
        <sphere radius="0.016"/>
      </geometry>
    </collision>
  </link>
  <joint name="FL_foot_fixed" type="fixed">
    <parent link="FL_shank"/>
    <child link="FL_foot"/>
    <origin xyz="0 0 -0.13" rpy="0 0 0"/>
  </joint>
  <link name="FR_hip_link">
    <inertial>
      <origin xyz="0 -0.025 0" rpy="0 0 0"/>
      <mass value="0.03"/>
      <inertia ixx="8.68e-06" ixy="0" ixz="0" iyy="4.859999999999998e-06" iyz="0" izz="8.68e-06"/>
    </inertial>
    <visual>
      <origin xyz="0 -0.025 0" rpy="1.5708 0 0"/>
      <geometry>
        <cylinder radius="0.018" length="0.05"/>
      </geometry>
      <material name="grey">
        <color rgba="0.4 0.4 0.45 1"/>
      </material>
    </visual>
    <collision>
      <origin xyz="0 -0.025 0" rpy="1.5708 0 0"/>
      <geometry>
        <cylinder radius="0.018" length="0.05"/>
      </geometry>
    </collision>
  </link>
  <joint name="FR_abd" type="revolute">
    <parent link="base_link"/>
    <child link="FR_hip_link"/>
    <origin xyz="0.12 -0.06 0" rpy="0 0 0"/>
    <axis xyz="-1.0 0 0"/>
    <limit lower="-1.0" upper="1.0" effort="0.2" velocity="6.0"/>
  </joint>
  <link name="FR_shank">
    <inertial>
      <origin xyz="0 0 -0.065" rpy="0 0 0"/>
      <mass value="0.015"/>
      <inertia ixx="2.1758750000000002e-05" ixy="0" ixz="0" iyy="2.1758750000000002e-05" iyz="0" izz="1.2675e-06"/>
    </inertial>
    <visual>
      <origin xyz="0 0 -0.065" rpy="0 0 0"/>
      <geometry>
        <cylinder radius="0.013" length="0.13"/>
      </geometry>
      <material name="green">
        <color rgba="0.2 0.7 0.3 1"/>
      </material>
    </visual>
    <collision>
      <origin xyz="0 0 -0.065" rpy="0 0 0"/>
      <geometry>
        <cylinder radius="0.013" length="0.13"/>
      </geometry>
    </collision>
  </link>
  <joint name="FR_knee" type="revolute">
    <parent link="FR_hip_link"/>
    <child link="FR_shank"/>
    <origin xyz="0 -0.05 0" rpy="0 0 0"/>
    <axis xyz="0 1 0"/>
    <limit lower="-1.5" upper="1.5" effort="0.2" velocity="6.0"/>
  </joint>
  <link name="FR_foot">
    <inertial>
      <origin xyz="0 0 0" rpy="0 0 0"/>
      <mass value="0.02"/>
      <inertia ixx="2.048e-06" ixy="0" ixz="0" iyy="2.048e-06" iyz="0" izz="2.048e-06"/>
    </inertial>
    <visual>
      <origin xyz="0 0 0" rpy="0 0 0"/>
      <geometry>
        <sphere radius="0.016"/>
      </geometry>
      <material name="grey">
        <color rgba="0.4 0.4 0.45 1"/>
      </material>
    </visual>
    <collision>
      <origin xyz="0 0 0" rpy="0 0 0"/>
      <geometry>
        <sphere radius="0.016"/>
      </geometry>
    </collision>
  </link>
  <joint name="FR_foot_fixed" type="fixed">
    <parent link="FR_shank"/>
    <child link="FR_foot"/>
    <origin xyz="0 0 -0.13" rpy="0 0 0"/>
  </joint>
  <link name="RL_hip_link">
    <inertial>
      <origin xyz="0 0.025 0" rpy="0 0 0"/>
      <mass value="0.03"/>
      <inertia ixx="8.68e-06" ixy="0" ixz="0" iyy="4.859999999999998e-06" iyz="0" izz="8.68e-06"/>
    </inertial>
    <visual>
      <origin xyz="0 0.025 0" rpy="1.5708 0 0"/>
      <geometry>
        <cylinder radius="0.018" length="0.05"/>
      </geometry>
      <material name="grey">
        <color rgba="0.4 0.4 0.45 1"/>
      </material>
    </visual>
    <collision>
      <origin xyz="0 0.025 0" rpy="1.5708 0 0"/>
      <geometry>
        <cylinder radius="0.018" length="0.05"/>
      </geometry>
    </collision>
  </link>
  <joint name="RL_abd" type="revolute">
    <parent link="base_link"/>
    <child link="RL_hip_link"/>
    <origin xyz="-0.12 0.06 0" rpy="0 0 0"/>
    <axis xyz="1.0 0 0"/>
    <limit lower="-1.0" upper="1.0" effort="0.2" velocity="6.0"/>
  </joint>
  <link name="RL_shank">
    <inertial>
      <origin xyz="0 0 -0.065" rpy="0 0 0"/>
      <mass value="0.015"/>
      <inertia ixx="2.1758750000000002e-05" ixy="0" ixz="0" iyy="2.1758750000000002e-05" iyz="0" izz="1.2675e-06"/>
    </inertial>
    <visual>
      <origin xyz="0 0 -0.065" rpy="0 0 0"/>
      <geometry>
        <cylinder radius="0.013" length="0.13"/>
      </geometry>
      <material name="green">
        <color rgba="0.2 0.7 0.3 1"/>
      </material>
    </visual>
    <collision>
      <origin xyz="0 0 -0.065" rpy="0 0 0"/>
      <geometry>
        <cylinder radius="0.013" length="0.13"/>
      </geometry>
    </collision>
  </link>
  <joint name="RL_knee" type="revolute">
    <parent link="RL_hip_link"/>
    <child link="RL_shank"/>
    <origin xyz="0 0.05 0" rpy="0 0 0"/>
    <axis xyz="0 1 0"/>
    <limit lower="-1.5" upper="1.5" effort="0.2" velocity="6.0"/>
  </joint>
  <link name="RL_foot">
    <inertial>
      <origin xyz="0 0 0" rpy="0 0 0"/>
      <mass value="0.02"/>
      <inertia ixx="2.048e-06" ixy="0" ixz="0" iyy="2.048e-06" iyz="0" izz="2.048e-06"/>
    </inertial>
    <visual>
      <origin xyz="0 0 0" rpy="0 0 0"/>
      <geometry>
        <sphere radius="0.016"/>
      </geometry>
      <material name="grey">
        <color rgba="0.4 0.4 0.45 1"/>
      </material>
    </visual>
    <collision>
      <origin xyz="0 0 0" rpy="0 0 0"/>
      <geometry>
        <sphere radius="0.016"/>
      </geometry>
    </collision>
  </link>
  <joint name="RL_foot_fixed" type="fixed">
    <parent link="RL_shank"/>
    <child link="RL_foot"/>
    <origin xyz="0 0 -0.13" rpy="0 0 0"/>
  </joint>
  <link name="RR_hip_link">
    <inertial>
      <origin xyz="0 -0.025 0" rpy="0 0 0"/>
      <mass value="0.03"/>
      <inertia ixx="8.68e-06" ixy="0" ixz="0" iyy="4.859999999999998e-06" iyz="0" izz="8.68e-06"/>
    </inertial>
    <visual>
      <origin xyz="0 -0.025 0" rpy="1.5708 0 0"/>
      <geometry>
        <cylinder radius="0.018" length="0.05"/>
      </geometry>
      <material name="grey">
        <color rgba="0.4 0.4 0.45 1"/>
      </material>
    </visual>
    <collision>
      <origin xyz="0 -0.025 0" rpy="1.5708 0 0"/>
      <geometry>
        <cylinder radius="0.018" length="0.05"/>
      </geometry>
    </collision>
  </link>
  <joint name="RR_abd" type="revolute">
    <parent link="base_link"/>
    <child link="RR_hip_link"/>
    <origin xyz="-0.12 -0.06 0" rpy="0 0 0"/>
    <axis xyz="-1.0 0 0"/>
    <limit lower="-1.0" upper="1.0" effort="0.2" velocity="6.0"/>
  </joint>
  <link name="RR_shank">
    <inertial>
      <origin xyz="0 0 -0.065" rpy="0 0 0"/>
      <mass value="0.015"/>
      <inertia ixx="2.1758750000000002e-05" ixy="0" ixz="0" iyy="2.1758750000000002e-05" iyz="0" izz="1.2675e-06"/>
    </inertial>
    <visual>
      <origin xyz="0 0 -0.065" rpy="0 0 0"/>
      <geometry>
        <cylinder radius="0.013" length="0.13"/>
      </geometry>
      <material name="green">
        <color rgba="0.2 0.7 0.3 1"/>
      </material>
    </visual>
    <collision>
      <origin xyz="0 0 -0.065" rpy="0 0 0"/>
      <geometry>
        <cylinder radius="0.013" length="0.13"/>
      </geometry>
    </collision>
  </link>
  <joint name="RR_knee" type="revolute">
    <parent link="RR_hip_link"/>
    <child link="RR_shank"/>
    <origin xyz="0 -0.05 0" rpy="0 0 0"/>
    <axis xyz="0 1 0"/>
    <limit lower="-1.5" upper="1.5" effort="0.2" velocity="6.0"/>
  </joint>
  <link name="RR_foot">
    <inertial>
      <origin xyz="0 0 0" rpy="0 0 0"/>
      <mass value="0.02"/>
      <inertia ixx="2.048e-06" ixy="0" ixz="0" iyy="2.048e-06" iyz="0" izz="2.048e-06"/>
    </inertial>
    <visual>
      <origin xyz="0 0 0" rpy="0 0 0"/>
      <geometry>
        <sphere radius="0.016"/>
      </geometry>
      <material name="grey">
        <color rgba="0.4 0.4 0.45 1"/>
      </material>
    </visual>
    <collision>
      <origin xyz="0 0 0" rpy="0 0 0"/>
      <geometry>
        <sphere radius="0.016"/>
      </geometry>
    </collision>
  </link>
  <joint name="RR_foot_fixed" type="fixed">
    <parent link="RR_shank"/>
    <child link="RR_foot"/>
    <origin xyz="0 0 -0.13" rpy="0 0 0"/>
  </joint>
</robot>
