<?xml version="1.0" ?>
<robot name="robot_dog">
  <link name="base_link">
    <inertial>
      <origin xyz="0 0 0" rpy="0 0 0"/>
      <mass value="1.2"/>
      <inertia ixx="0.0017999999999999997" ixy="0" ixz="0" iyy="0.00936" iyz="0" izz="0.010439999999999998"/>
    </inertial>
    <visual>
      <origin xyz="0 0 0" rpy="0 0 0"/>
      <geometry>
        <box size="0.3 0.12 0.06"/>
      </geometry>
      <material name="blue">
        <color rgba="0.2 0.4 0.8 1"/>
      </material>
    </visual>
    <collision>
      <origin xyz="0 0 0" rpy="0 0 0"/>
      <geometry>
        <box size="0.3 0.12 0.06"/>
      </geometry>
    </collision>
  </link>
  <link name="FL_hip_link">
    <inertial>
      <origin xyz="0 0.02 0" rpy="0 0 0"/>
      <mass value="0.1"/>
      <inertia ixx="2.143333333333333e-05" ixy="0" ixz="0" iyy="1.6199999999999997e-05" iyz="0" izz="2.143333333333333e-05"/>
    </inertial>
    <visual>
      <origin xyz="0 0.02 0" rpy="1.5708 0 0"/>
      <geometry>
        <cylinder radius="0.018" length="0.04"/>
      </geometry>
      <material name="grey">
        <color rgba="0.4 0.4 0.45 1"/>
      </material>
    </visual>
    <collision>
      <origin xyz="0 0.02 0" rpy="1.5708 0 0"/>
      <geometry>
        <cylinder radius="0.018" length="0.04"/>
      </geometry>
    </collision>
  </link>
  <joint name="FL_hip" type="revolute">
    <parent link="base_link"/>
    <child link="FL_hip_link"/>
    <origin xyz="0.12 0.06 0" rpy="0 0 0"/>
    <axis xyz="1 0 0"/>
    <limit lower="-0.8" upper="0.8" effort="2.0" velocity="8.0"/>
  </joint>
  <link name="FL_thigh">
    <inertial>
      <origin xyz="0 0 -0.055" rpy="0 0 0"/>
      <mass value="0.12"/>
      <inertia ixx="0.00012687999999999998" ixy="0" ixz="0" iyy="0.00012687999999999998" iyz="0" izz="1.1760000000000001e-05"/>
    </inertial>
    <visual>
      <origin xyz="0 0 -0.055" rpy="0 0 0"/>
      <geometry>
        <cylinder radius="0.014" length="0.11"/>
      </geometry>
      <material name="grey">
        <color rgba="0.4 0.4 0.45 1"/>
      </material>
    </visual>
    <collision>
      <origin xyz="0 0 -0.055" rpy="0 0 0"/>
      <geometry>
        <cylinder radius="0.014" length="0.11"/>
      </geometry>
    </collision>
  </link>
  <joint name="FL_thigh" type="revolute">
    <parent link="FL_hip_link"/>
    <child link="FL_thigh"/>
    <origin xyz="0 0.04 0" rpy="0 0 0"/>
    <axis xyz="0 1 0"/>
    <limit lower="-1.6" upper="1.6" effort="2.0" velocity="8.0"/>
  </joint>
  <link name="FL_shank">
    <inertial>
      <origin xyz="0 0 -0.06" rpy="0 0 0"/>
      <mass value="0.08"/>
      <inertia ixx="9.887999999999999e-05" ixy="0" ixz="0" iyy="9.887999999999999e-05" iyz="0" izz="5.76e-06"/>
    </inertial>
    <visual>
      <origin xyz="0 0 -0.06" rpy="0 0 0"/>
      <geometry>
        <cylinder radius="0.012" length="0.12"/>
      </geometry>
      <material name="grey">
        <color rgba="0.4 0.4 0.45 1"/>
      </material>
    </visual>
    <collision>
      <origin xyz="0 0 -0.06" rpy="0 0 0"/>
      <geometry>
        <cylinder radius="0.012" length="0.12"/>
      </geometry>
    </collision>
  </link>
  <joint name="FL_knee" type="revolute">
    <parent link="FL_thigh"/>
    <child link="FL_shank"/>
    <origin xyz="0 0 -0.11" rpy="0 0 0"/>
    <axis xyz="0 1 0"/>
    <limit lower="-2.6" upper="-0.2" effort="2.0" velocity="8.0"/>
  </joint>
  <link name="FL_foot">
    <inertial>
      <origin xyz="0 0 0" rpy="0 0 0"/>
      <mass value="0.02"/>
      <inertia ixx="2.048e-06" ixy="0" ixz="0" iyy="2.048e-06" iyz="0" izz="2.048e-06"/>
    </inertial>
    <visual>
      <origin xyz="0 0 0" rpy="0 0 0"/>
      <geometry>
        <sphere radius="0.016"/>
      </geometry>
      <material name="grey">
        <color rgba="0.4 0.4 0.45 1"/>
      </material>
    </visual>
    <collision>
      <origin xyz="0 0 0" rpy="0 0 0"/>
      <geometry>
        <sphere radius="0.016"/>
      </geometry>
    </collision>
  </link>
  <joint name="FL_foot_fixed" type="fixed">
    <parent link="FL_shank"/>
    <child link="FL_foot"/>
    <origin xyz="0 0 -0.12" rpy="0 0 0"/>
  </joint>
  <link name="FR_hip_link">
    <inertial>
      <origin xyz="0 -0.02 0" rpy="0 0 0"/>
      <mass value="0.1"/>
      <inertia ixx="2.143333333333333e-05" ixy="0" ixz="0" iyy="1.6199999999999997e-05" iyz="0" izz="2.143333333333333e-05"/>
    </inertial>
    <visual>
      <origin xyz="0 -0.02 0" rpy="1.5708 0 0"/>
      <geometry>
        <cylinder radius="0.018" length="0.04"/>
      </geometry>
      <material name="grey">
        <color rgba="0.4 0.4 0.45 1"/>
      </material>
    </visual>
    <collision>
      <origin xyz="0 -0.02 0" rpy="1.5708 0 0"/>
      <geometry>
        <cylinder radius="0.018" length="0.04"/>
      </geometry>
    </collision>
  </link>
  <joint name="FR_hip" type="revolute">
    <parent link="base_link"/>
    <child link="FR_hip_link"/>
    <origin xyz="0.12 -0.06 0" rpy="0 0 0"/>
    <axis xyz="1 0 0"/>
    <limit lower="-0.8" upper="0.8" effort="2.0" velocity="8.0"/>
  </joint>
  <link name="FR_thigh">
    <inertial>
      <origin xyz="0 0 -0.055" rpy="0 0 0"/>
      <mass value="0.12"/>
      <inertia ixx="0.00012687999999999998" ixy="0" ixz="0" iyy="0.00012687999999999998" iyz="0" izz="1.1760000000000001e-05"/>
    </inertial>
    <visual>
      <origin xyz="0 0 -0.055" rpy="0 0 0"/>
      <geometry>
        <cylinder radius="0.014" length="0.11"/>
      </geometry>
      <material name="grey">
        <color rgba="0.4 0.4 0.45 1"/>
      </material>
    </visual>
    <collision>
      <origin xyz="0 0 -0.055" rpy="0 0 0"/>
      <geometry>
        <cylinder radius="0.014" length="0.11"/>
      </geometry>
    </collision>
  </link>
  <joint name="FR_thigh" type="revolute">
    <parent link="FR_hip_link"/>
    <child link="FR_thigh"/>
    <origin xyz="0 -0.04 0" rpy="0 0 0"/>
    <axis xyz="0 1 0"/>
    <limit lower="-1.6" upper="1.6" effort="2.0" velocity="8.0"/>
  </joint>
  <link name="FR_shank">
    <inertial>
      <origin xyz="0 0 -0.06" rpy="0 0 0"/>
      <mass value="0.08"/>
      <inertia ixx="9.887999999999999e-05" ixy="0" ixz="0" iyy="9.887999999999999e-05" iyz="0" izz="5.76e-06"/>
    </inertial>
    <visual>
      <origin xyz="0 0 -0.06" rpy="0 0 0"/>
      <geometry>
        <cylinder radius="0.012" length="0.12"/>
      </geometry>
      <material name="grey">
        <color rgba="0.4 0.4 0.45 1"/>
      </material>
    </visual>
    <collision>
      <origin xyz="0 0 -0.06" rpy="0 0 0"/>
      <geometry>
        <cylinder radius="0.012" length="0.12"/>
      </geometry>
    </collision>
  </link>
  <joint name="FR_knee" type="revolute">
    <parent link="FR_thigh"/>
    <child link="FR_shank"/>
    <origin xyz="0 0 -0.11" rpy="0 0 0"/>
    <axis xyz="0 1 0"/>
    <limit lower="-2.6" upper="-0.2" effort="2.0" velocity="8.0"/>
  </joint>
  <link name="FR_foot">
    <inertial>
      <origin xyz="0 0 0" rpy="0 0 0"/>
      <mass value="0.02"/>
      <inertia ixx="2.048e-06" ixy="0" ixz="0" iyy="2.048e-06" iyz="0" izz="2.048e-06"/>
    </inertial>
    <visual>
      <origin xyz="0 0 0" rpy="0 0 0"/>
      <geometry>
        <sphere radius="0.016"/>
      </geometry>
      <material name="grey">
        <color rgba="0.4 0.4 0.45 1"/>
      </material>
    </visual>
    <collision>
      <origin xyz="0 0 0" rpy="0 0 0"/>
      <geometry>
        <sphere radius="0.016"/>
      </geometry>
    </collision>
  </link>
  <joint name="FR_foot_fixed" type="fixed">
    <parent link="FR_shank"/>
    <child link="FR_foot"/>
    <origin xyz="0 0 -0.12" rpy="0 0 0"/>
  </joint>
  <link name="RL_hip_link">
    <inertial>
      <origin xyz="0 0.02 0" rpy="0 0 0"/>
      <mass value="0.1"/>
      <inertia ixx="2.143333333333333e-05" ixy="0" ixz="0" iyy="1.6199999999999997e-05" iyz="0" izz="2.143333333333333e-05"/>
    </inertial>
    <visual>
      <origin xyz="0 0.02 0" rpy="1.5708 0 0"/>
      <geometry>
        <cylinder radius="0.018" length="0.04"/>
      </geometry>
      <material name="grey">
        <color rgba="0.4 0.4 0.45 1"/>
      </material>
    </visual>
    <collision>
      <origin xyz="0 0.02 0" rpy="1.5708 0 0"/>
      <geometry>
        <cylinder radius="0.018" length="0.04"/>
      </geometry>
    </collision>
  </link>
  <joint name="RL_hip" type="revolute">
    <parent link="base_link"/>
    <child link="RL_hip_link"/>
    <origin xyz="-0.12 0.06 0" rpy="0 0 0"/>
    <axis xyz="1 0 0"/>
    <limit lower="-0.8" upper="0.8" effort="2.0" velocity="8.0"/>
  </joint>
  <link name="RL_thigh">
    <inertial>
      <origin xyz="0 0 -0.055" rpy="0 0 0"/>
      <mass value="0.12"/>
      <inertia ixx="0.00012687999999999998" ixy="0" ixz="0" iyy="0.00012687999999999998" iyz="0" izz="1.1760000000000001e-05"/>
    </inertial>
    <visual>
      <origin xyz="0 0 -0.055" rpy="0 0 0"/>
      <geometry>
        <cylinder radius="0.014" length="0.11"/>
      </geometry>
      <material name="grey">
        <color rgba="0.4 0.4 0.45 1"/>
      </material>
    </visual>
    <collision>
      <origin xyz="0 0 -0.055" rpy="0 0 0"/>
      <geometry>
        <cylinder radius="0.014" length="0.11"/>
      </geometry>
    </collision>
  </link>
  <joint name="RL_thigh" type="revolute">
    <parent link="RL_hip_link"/>
    <child link="RL_thigh"/>
    <origin xyz="0 0.04 0" rpy="0 0 0"/>
    <axis xyz="0 1 0"/>
    <limit lower="-1.6" upper="1.6" effort="2.0" velocity="8.0"/>
  </joint>
  <link name="RL_shank">
    <inertial>
      <origin xyz="0 0 -0.06" rpy="0 0 0"/>
      <mass value="0.08"/>
      <inertia ixx="9.887999999999999e-05" ixy="0" ixz="0" iyy="9.887999999999999e-05" iyz="0" izz="5.76e-06"/>
    </inertial>
    <visual>
      <origin xyz="0 0 -0.06" rpy="0 0 0"/>
      <geometry>
        <cylinder radius="0.012" length="0.12"/>
      </geometry>
      <material name="grey">
        <color rgba="0.4 0.4 0.45 1"/>
      </material>
    </visual>
    <collision>
      <origin xyz="0 0 -0.06" rpy="0 0 0"/>
      <geometry>
        <cylinder radius="0.012" length="0.12"/>
      </geometry>
    </collision>
  </link>
  <joint name="RL_knee" type="revolute">
    <parent link="RL_thigh"/>
    <child link="RL_shank"/>
    <origin xyz="0 0 -0.11" rpy="0 0 0"/>
    <axis xyz="0 1 0"/>
    <limit lower="-2.6" upper="-0.2" effort="2.0" velocity="8.0"/>
  </joint>
  <link name="RL_foot">
    <inertial>
      <origin xyz="0 0 0" rpy="0 0 0"/>
      <mass value="0.02"/>
      <inertia ixx="2.048e-06" ixy="0" ixz="0" iyy="2.048e-06" iyz="0" izz="2.048e-06"/>
    </inertial>
    <visual>
      <origin xyz="0 0 0" rpy="0 0 0"/>
      <geometry>
        <sphere radius="0.016"/>
      </geometry>
      <material name="grey">
        <color rgba="0.4 0.4 0.45 1"/>
      </material>
    </visual>
    <collision>
      <origin xyz="0 0 0" rpy="0 0 0"/>
      <geometry>
        <sphere radius="0.016"/>
      </geometry>
    </collision>
  </link>
  <joint name="RL_foot_fixed" type="fixed">
    <parent link="RL_shank"/>
    <child link="RL_foot"/>
    <origin xyz="0 0 -0.12" rpy="0 0 0"/>
  </joint>
  <link name="RR_hip_link">
    <inertial>
      <origin xyz="0 -0.02 0" rpy="0 0 0"/>
      <mass value="0.1"/>
      <inertia ixx="2.143333333333333e-05" ixy="0" ixz="0" iyy="1.6199999999999997e-05" iyz="0" izz="2.143333333333333e-05"/>
    </inertial>
    <visual>
      <origin xyz="0 -0.02 0" rpy="1.5708 0 0"/>
      <geometry>
        <cylinder radius="0.018" length="0.04"/>
      </geometry>
      <material name="grey">
        <color rgba="0.4 0.4 0.45 1"/>
      </material>
    </visual>
    <collision>
      <origin xyz="0 -0.02 0" rpy="1.5708 0 0"/>
      <geometry>
        <cylinder radius="0.018" length="0.04"/>
      </geometry>
    </collision>
  </link>
  <joint name="RR_hip" type="revolute">
    <parent link="base_link"/>
    <child link="RR_hip_link"/>
    <origin xyz="-0.12 -0.06 0" rpy="0 0 0"/>
    <axis xyz="1 0 0"/>
    <limit lower="-0.8" upper="0.8" effort="2.0" velocity="8.0"/>
  </joint>
  <link name="RR_thigh">
    <inertial>
      <origin xyz="0 0 -0.055" rpy="0 0 0"/>
      <mass value="0.12"/>
      <inertia ixx="0.00012687999999999998" ixy="0" ixz="0" iyy="0.00012687999999999998" iyz="0" izz="1.1760000000000001e-05"/>
    </inertial>
    <visual>
      <origin xyz="0 0 -0.055" rpy="0 0 0"/>
      <geometry>
        <cylinder radius="0.014" length="0.11"/>
      </geometry>
      <material name="grey">
        <color rgba="0.4 0.4 0.45 1"/>
      </material>
    </visual>
    <collision>
      <origin xyz="0 0 -0.055" rpy="0 0 0"/>
      <geometry>
        <cylinder radius="0.014" length="0.11"/>
      </geometry>
    </collision>
  </link>
  <joint name="RR_thigh" type="revolute">
    <parent link="RR_hip_link"/>
    <child link="RR_thigh"/>
    <origin xyz="0 -0.04 0" rpy="0 0 0"/>
    <axis xyz="0 1 0"/>
    <limit lower="-1.6" upper="1.6" effort="2.0" velocity="8.0"/>
  </joint>
  <link name="RR_shank">
    <inertial>
      <origin xyz="0 0 -0.06" rpy="0 0 0"/>
      <mass value="0.08"/>
      <inertia ixx="9.887999999999999e-05" ixy="0" ixz="0" iyy="9.887999999999999e-05" iyz="0" izz="5.76e-06"/>
    </inertial>
    <visual>
      <origin xyz="0 0 -0.06" rpy="0 0 0"/>
      <geometry>
        <cylinder radius="0.012" length="0.12"/>
      </geometry>
      <material name="grey">
        <color rgba="0.4 0.4 0.45 1"/>
      </material>
    </visual>
    <collision>
      <origin xyz="0 0 -0.06" rpy="0 0 0"/>
      <geometry>
        <cylinder radius="0.012" length="0.12"/>
      </geometry>
    </collision>
  </link>
  <joint name="RR_knee" type="revolute">
    <parent link="RR_thigh"/>
    <child link="RR_shank"/>
    <origin xyz="0 0 -0.11" rpy="0 0 0"/>
    <axis xyz="0 1 0"/>
    <limit lower="-2.6" upper="-0.2" effort="2.0" velocity="8.0"/>
  </joint>
  <link name="RR_foot">
    <inertial>
      <origin xyz="0 0 0" rpy="0 0 0"/>
      <mass value="0.02"/>
      <inertia ixx="2.048e-06" ixy="0" ixz="0" iyy="2.048e-06" iyz="0" izz="2.048e-06"/>
    </inertial>
    <visual>
      <origin xyz="0 0 0" rpy="0 0 0"/>
      <geometry>
        <sphere radius="0.016"/>
      </geometry>
      <material name="grey">
        <color rgba="0.4 0.4 0.45 1"/>
      </material>
    </visual>
    <collision>
      <origin xyz="0 0 0" rpy="0 0 0"/>
      <geometry>
        <sphere radius="0.016"/>
      </geometry>
    </collision>
  </link>
  <joint name="RR_foot_fixed" type="fixed">
    <parent link="RR_shank"/>
    <child link="RR_foot"/>
    <origin xyz="0 0 -0.12" rpy="0 0 0"/>
  </joint>
</robot>
