<?xml version="1.0" ?>
<mujoco model="robot_dog">
  <compiler angle="radian" autolimits="true"/>
  <option timestep="0.004" gravity="0 0 -9.81" integrator="implicitfast"/>
  <default>
    <joint armature="0.01" damping="0.3"/>
    <geom rgba="0.4 0.4 0.45 1" friction="1 0.1 0.1"/>
    <default class="srv">
      <position kp="8" forcerange="-2.5 2.5"/>
    </default>
  </default>
  <asset>
    <texture name="grid" type="2d" builtin="checker" rgb1="0.2 0.2 0.2" rgb2="0.3 0.3 0.3" width="256" height="256"/>
    <material name="grid" texture="grid" texrepeat="8 8" reflectance="0.1"/>
  </asset>
  <worldbody>
    <light pos="0 0 2" dir="0 0 -1" diffuse="0.8 0.8 0.8"/>
    <geom name="floor" type="plane" size="5 5 0.1" material="grid" condim="3"/>
    <body name="trunk" pos="0 0 0.27">
      <freejoint name="root"/>
      <geom type="box" size="0.15 0.06 0.03" mass="1.2" rgba="0.2 0.4 0.8 1"/>
      <body name="FL_hip_link" pos="0.12 0.06 0">
        <joint name="FL_hip" axis="1 0 0" range="-0.8 0.8"/>
        <geom type="cylinder" fromto="0 0 0 0 0.04 0" size="0.018" mass="0.1"/>
        <body name="FL_thigh" pos="0 0.04 0">
          <joint name="FL_thigh" axis="0 1 0" range="-1.6 1.6"/>
          <geom type="cylinder" fromto="0 0 0 0 0 -0.11" size="0.014" mass="0.12"/>
          <body name="FL_shank" pos="0 0 -0.11">
            <joint name="FL_knee" axis="0 1 0" range="-2.6 -0.2"/>
            <geom type="cylinder" fromto="0 0 0 0 0 -0.12" size="0.012" mass="0.08"/>
            <geom type="sphere" pos="0 0 -0.12" size="0.016" mass="0.02" rgba="0.1 0.1 0.1 1"/>
          </body>
        </body>
      </body>
      <body name="FR_hip_link" pos="0.12 -0.06 0">
        <joint name="FR_hip" axis="1 0 0" range="-0.8 0.8"/>
        <geom type="cylinder" fromto="0 0 0 0 -0.04 0" size="0.018" mass="0.1"/>
        <body name="FR_thigh" pos="0 -0.04 0">
          <joint name="FR_thigh" axis="0 1 0" range="-1.6 1.6"/>
          <geom type="cylinder" fromto="0 0 0 0 0 -0.11" size="0.014" mass="0.12"/>
          <body name="FR_shank" pos="0 0 -0.11">
            <joint name="FR_knee" axis="0 1 0" range="-2.6 -0.2"/>
            <geom type="cylinder" fromto="0 0 0 0 0 -0.12" size="0.012" mass="0.08"/>
            <geom type="sphere" pos="0 0 -0.12" size="0.016" mass="0.02" rgba="0.1 0.1 0.1 1"/>
          </body>
        </body>
      </body>
      <body name="RL_hip_link" pos="-0.12 0.06 0">
        <joint name="RL_hip" axis="1 0 0" range="-0.8 0.8"/>
        <geom type="cylinder" fromto="0 0 0 0 0.04 0" size="0.018" mass="0.1"/>
        <body name="RL_thigh" pos="0 0.04 0">
          <joint name="RL_thigh" axis="0 1 0" range="-1.6 1.6"/>
          <geom type="cylinder" fromto="0 0 0 0 0 -0.11" size="0.014" mass="0.12"/>
          <body name="RL_shank" pos="0 0 -0.11">
            <joint name="RL_knee" axis="0 1 0" range="-2.6 -0.2"/>
            <geom type="cylinder" fromto="0 0 0 0 0 -0.12" size="0.012" mass="0.08"/>
            <geom type="sphere" pos="0 0 -0.12" size="0.016" mass="0.02" rgba="0.1 0.1 0.1 1"/>
          </body>
        </body>
      </body>
      <body name="RR_hip_link" pos="-0.12 -0.06 0">
        <joint name="RR_hip" axis="1 0 0" range="-0.8 0.8"/>
        <geom type="cylinder" fromto="0 0 0 0 -0.04 0" size="0.018" mass="0.1"/>
        <body name="RR_thigh" pos="0 -0.04 0">
          <joint name="RR_thigh" axis="0 1 0" range="-1.6 1.6"/>
          <geom type="cylinder" fromto="0 0 0 0 0 -0.11" size="0.014" mass="0.12"/>
          <body name="RR_shank" pos="0 0 -0.11">
            <joint name="RR_knee" axis="0 1 0" range="-2.6 -0.2"/>
            <geom type="cylinder" fromto="0 0 0 0 0 -0.12" size="0.012" mass="0.08"/>
            <geom type="sphere" pos="0 0 -0.12" size="0.016" mass="0.02" rgba="0.1 0.1 0.1 1"/>
          </body>
        </body>
      </body>
    </body>
  </worldbody>
  <actuator>
    <position class="srv" name="FL_hip_act" joint="FL_hip" ctrlrange="-0.8 0.8"/>
    <position class="srv" name="FL_thigh_act" joint="FL_thigh" ctrlrange="-1.6 1.6"/>
    <position class="srv" name="FL_knee_act" joint="FL_knee" ctrlrange="-2.6 -0.2"/>
    <position class="srv" name="FR_hip_act" joint="FR_hip" ctrlrange="-0.8 0.8"/>
    <position class="srv" name="FR_thigh_act" joint="FR_thigh" ctrlrange="-1.6 1.6"/>
    <position class="srv" name="FR_knee_act" joint="FR_knee" ctrlrange="-2.6 -0.2"/>
    <position class="srv" name="RL_hip_act" joint="RL_hip" ctrlrange="-0.8 0.8"/>
    <position class="srv" name="RL_thigh_act" joint="RL_thigh" ctrlrange="-1.6 1.6"/>
    <position class="srv" name="RL_knee_act" joint="RL_knee" ctrlrange="-2.6 -0.2"/>
    <position class="srv" name="RR_hip_act" joint="RR_hip" ctrlrange="-0.8 0.8"/>
    <position class="srv" name="RR_thigh_act" joint="RR_thigh" ctrlrange="-1.6 1.6"/>
    <position class="srv" name="RR_knee_act" joint="RR_knee" ctrlrange="-2.6 -0.2"/>
  </actuator>
</mujoco>
